<?xml version="1.0"?>
<robot xmlns:xacro="http://www.ros.org/wiki/xacro" name="ReU_module">
<xacro:macro name="module" params="module_num">
<xacro:property name="next_module_num" value="${module_num+1}" />
	<link name="module_${module_num}">
		<visual>
			<origin rpy="0 0 0" xyz="0 0 0"/>
			<geometry>
				<mesh filename="package://snakelib_description/RSNAKE_snake/meshes/R8_16_link.stl" scale="0.001 0.001 0.001"/>
			</geometry>
			<material name="black">
        			<color rgba="0 0 0 0.9"/>
      			</material>
		</visual>
		<collision>
			<origin rpy="0 1.57 0" xyz="0.118 0 0"/>
			<geometry>
				<cylinder length="0.1450" radius="0.05"/>
			</geometry>
		</collision>
		<inertial>
			<mass value="1.072"/>
			<inertia ixx="0.0104" ixy="0.0" ixz="0.0" iyy="0.0104" iyz="0.0" izz="0.0104"/>
		</inertial>
	</link>

	<joint name="module_${module_num}_to_${next_module_num}" type="revolute">
		<parent link="module_${module_num}"/>
		<child link="module_${next_module_num}"/>
		<axis xyz="0 0 1"/>
		<origin rpy="1.57 0 0" xyz="0.145 0 0"/>
		<limit effort="16.0" lower="-1.57" upper="1.57" velocity="0.25"/>
	</joint>
</xacro:macro>
</robot>
